
# ch11. 예외와 예외처리
## 11.1 Error 객체
js에는 내장된 Error 객체가 있고, 이는 에러 처리에 간편하게 사용할 수 있다.
Error 인스턴스를 만들면서 에러 메시지를 지정할 수 있다.
```javascript
const  err=new  Error('invalid email');
```
Error인스턴스를 만드는 것만으로는 아무 일도 일어나지 않는다.
이 인스턴스는 에러와 통신하는 수단이다.
```javascript
//이메일 주소가 올바르면 이메일 주소를 반환
//바르지 않다면 Error 인스턴스를 반환
function  validateEmail(email){
	return  email.match(/@/)?
		email:
		new  Error(`invalid email:${email}`);
}
```
삼항연산자 num2 = **(**num1 == 10**)** ? 100 : 200;
```javascript
const  email="jane@doe.com";
const  validatedEmail=validateEmail(email);
if(validateEmail  instanceof  Error){
	console.error(`Error:${validatedEmail.message}`);
}else{
	console.log(`Valid email:${validatedEmail}`);
}
//에러 메시지는 message 프로퍼티에 있음
//if else문으로 예외처리를 
```
## 11.2 try/catch와 예외처리
예외처리는 try...catch문을 사용함
예상친 못한 예외에 대처하려면 try...catch문으로 코드 전체를 감쌀 수 있다.
```javascript
const  email=null;
try{
	const  validatedEmail=validateEmail(email);
	if(validatedEmail  instanceof  Error){
		console.error(`Error:${validateEmail.message}`);
	}
	else{
		console.log(`Valid email:${validatedEmail}`);
	}
}catch(err){
	console.error(`Error:${err.message}`);
}
```
에러가 일어나는 즉시 catch 블록으로 이동한다.
validateEmail을 호출한 다음에 있는 if문은 실행되지 않는다.
## 11.3 에러 일으키기
자바스크립트가 에러를 일으키기만 기다릴 필요 없이 직접 에러를 일으켜서(throw,raise) 예외처리작업을 시작할 수 있다.
js는 에러를 일으킬 때 꼭 객체만이 아니라 숫자나 문자열등 어떤 값이든 catch절에 넘길 수 있다.
BUT) Error 스턴스를 넘기는 것이 가장 편리하다.
대부분의 catch블록은 Error인스턴스를 받을 것이라고 간주하고 만든다.
```javascript
function  billPay(amount,payee,account){
	if(amount>account.balance)
		throw  new  Error("insufficient funds");
	account.transfer(payee,amount);
}
```
throw를 호출하면 현재 함수(function)는 즉시 실행을 멈춘다.
account,transfer가 호출되지 않는다.
## 11.4 예외 처리와 호출 스택
호출 스택: 완료되지 않은 함수가 쌓이는 것
함수 a-->함수 b-->함수 c : 함수 c가 실행을 마칠 때 실행 흐름은 함수 b로 돌아간다. b가 실행을 마칠 때 실행 흐름은 함수 a로 돌아간다.
==c가 실행 중일 때는 a와 b는 완료될 수 없다.

if c에서 에러가 난다면 b,a도 에러가 난다.
에러는 호출 스택 어디에서든 캐치 가능하고
만약 캐치하지 않으면 인터프리터는 프로그램 중단-->프로그램 충돌의 원인
```javascript
function  a(){
	console.log('a:calling b');
	b();
	console.log('a:done');
}
function  b(){
	console.log('b:calling c');
	c();
	console.log('b:done');
}
function  c(){
	console.log('c:throwing error');
	throw  new  Error('c error');
	console.log('c:done');
}
function  d(){
	console.log('d:calling c');
	c();
	console.log('d:done');
}

try{
	a();
}
catch(err){
	console.log(err.stack);
}

try{
	d();
}catch(err){
	console.log(err.stack);
}
```
실행결과
a:calling b
b:calling c
c:throwing error

d:calling c
c:throwing error
Error: c error

## 11.5 try...catch...finally
try블록의 코드가 http 연결이나 파일 같은 일종의 '자원'을 처리할 때가 있다.-->어느 시점에서는 자원을 해제해야 한다.
따라서 finally블록이 필요하다. finally블록은 에러가 일어나든, 일어나지 않든 반드시 호출된다.
```javascript
try{
	console.log("this line is executed...");
	throw  new  Error("whoops");
	console.log("this line is not...");
}catch(err){
	console.log("there was an error");
}finally{
	console.log("...always executed");
	console.log("perform cleanup here");
}
```
실행결과

this line is executed...
there was an error
...always executed
perform cleanup here

//throw 문 주석
this line is executed...
this line is not...
...always executed
perform cleanup here

**-->finally문은 항상 호출이 됨**
